Traceback (most recent call last):
  File "/opt/hostedtoolcache/Python/3.10.15/x64/lib/python3.10/site-packages/jupyter_cache/executors/utils.py", line 58, in single_nb_execution
    executenb(
  File "/opt/hostedtoolcache/Python/3.10.15/x64/lib/python3.10/site-packages/nbclient/client.py", line 1314, in execute
    return NotebookClient(nb=nb, resources=resources, km=km, **kwargs).execute()
  File "/opt/hostedtoolcache/Python/3.10.15/x64/lib/python3.10/site-packages/jupyter_core/utils/__init__.py", line 165, in wrapped
    return loop.run_until_complete(inner)
  File "/opt/hostedtoolcache/Python/3.10.15/x64/lib/python3.10/asyncio/base_events.py", line 649, in run_until_complete
    return future.result()
  File "/opt/hostedtoolcache/Python/3.10.15/x64/lib/python3.10/site-packages/nbclient/client.py", line 709, in async_execute
    await self.async_execute_cell(
  File "/opt/hostedtoolcache/Python/3.10.15/x64/lib/python3.10/site-packages/nbclient/client.py", line 1062, in async_execute_cell
    await self._check_raise_for_error(cell, cell_index, exec_reply)
  File "/opt/hostedtoolcache/Python/3.10.15/x64/lib/python3.10/site-packages/nbclient/client.py", line 918, in _check_raise_for_error
    raise CellExecutionError.from_cell_and_msg(cell, exec_reply_content)
nbclient.exceptions.CellExecutionError: An error occurred while executing the following cell:
------------------
# gather all the phases in the "cifs" directory
all_cifs = list(Path("cifs").glob("*.cif"))

search_results = search_phases(
    pattern_path=pattern_path,
    phases=all_cifs,
    wavelength="Cu",
    instrument_name="Aeris-fds-Pixcel1d-Medipix3",
)
------------------


[0;31m---------------------------------------------------------------------------[0m
[0;31mTypeError[0m                                 Traceback (most recent call last)
Cell [0;32mIn[5], line 4[0m
[1;32m      1[0m [38;5;66;03m# gather all the phases in the "cifs" directory[39;00m
[1;32m      2[0m all_cifs [38;5;241m=[39m [38;5;28mlist[39m(Path([38;5;124m"[39m[38;5;124mcifs[39m[38;5;124m"[39m)[38;5;241m.[39mglob([38;5;124m"[39m[38;5;124m*.cif[39m[38;5;124m"[39m))
[0;32m----> 4[0m search_results [38;5;241m=[39m [43msearch_phases[49m[43m([49m
[1;32m      5[0m [43m    [49m[43mpattern_path[49m[38;5;241;43m=[39;49m[43mpattern_path[49m[43m,[49m
[1;32m      6[0m [43m    [49m[43mphases[49m[38;5;241;43m=[39;49m[43mall_cifs[49m[43m,[49m
[1;32m      7[0m [43m    [49m[43mwavelength[49m[38;5;241;43m=[39;49m[38;5;124;43m"[39;49m[38;5;124;43mCu[39;49m[38;5;124;43m"[39;49m[43m,[49m
[1;32m      8[0m [43m    [49m[43minstrument_name[49m[38;5;241;43m=[39;49m[38;5;124;43m"[39;49m[38;5;124;43mAeris-fds-Pixcel1d-Medipix3[39;49m[38;5;124;43m"[39;49m[43m,[49m
[1;32m      9[0m [43m)[49m

[0;31mTypeError[0m: search_phases() got an unexpected keyword argument 'instrument_name'

